Workbook

Sheet nantucket
A1: Day | B1: Index | C1: Hour | D1: Location ID | E1: Network Node Description | F1: MW Factor | G1: Energy Component | H1: Congestion Component | I1: Marginal Loss Component | J1: Price | K1: N-1 Shortfall
A2: 2024-08-02 | B2: 786 | C2: 18 | D2: 16255 | E2: LD.CANDLE 13.2 | F2: 57 | G2: 63.86 | H2: 0 | I2: 1.51 | J2: 65.37 | K2: =#REF!-resources!$B$14 -> #REF!
A3: 2024-08-03 | B3: 811 | C3: 19 | D3: 16255 | E3: LD.CANDLE 13.2 | F3: 57 | G3: 29.63 | H3: 0 | I3: 0.81 | J3: 30.44 | K3: =#REF!-resources!$B$14 -> #REF!
A4: 2024-07-16 | B4: 378 | C4: 18 | D4: 16255 | E4: LD.CANDLE 13.2 | F4: 56 | G4: 110.64 | H4: 0.02 | I4: 2.46 | J4: 113.12 | K4: =#REF!-resources!$B$14 -> #REF!
A5: 2024-07-16 | B5: 379 | C5: 19 | D5: 16255 | E5: LD.CANDLE 13.2 | F5: 56 | G5: 260.14 | H5: 0 | I5: 5.62 | J5: 265.76 | K5: =#REF!-resources!$B$14 -> #REF!
A6: 2024-08-02 | B6: 787 | C6: 19 | D6: 16255 | E6: LD.CANDLE 13.2 | F6: 56 | G6: 37.75 | H6: 0 | I6: 0.96 | J6: 38.71 | K6: =#REF!-resources!$B$14 -> #REF!
A7: 2024-08-03 | B7: 810 | C7: 18 | D7: 16255 | E7: LD.CANDLE 13.2 | F7: 56 | G7: 43.69 | H7: 0 | I7: 0.93 | J7: 44.62 | K7: =#REF!-resources!$B$14 -> #REF!
A8: 2024-07-15 | B8: 355 | C8: 19 | D8: 16255 | E8: LD.CANDLE 13.2 | F8: 55 | G8: 56.39 | H8: 0 | I8: 1.62 | J8: 58.01 | K8: =#REF!-resources!$B$14 -> #REF!
A9: 2024-07-16 | B9: 380 | C9: 20 | D9: 16255 | E9: LD.CANDLE 13.2 | F9: 55 | G9: 64.52 | H9: 0 | I9: 1.5 | J9: 66.02 | K9: =#REF!-resources!$B$14 -> #REF!
A10: 2024-08-02 | B10: 788 | C10: 20 | D10: 16255 | E10: LD.CANDLE 13.2 | F10: 55 | G10: 39.94 | H10: 0 | I10: 0.85 | J10: 40.79 | K10: =#REF!-resources!$B$14 -> #REF!
A11: 2024-08-03 | B11: 812 | C11: 20 | D11: 16255 | E11: LD.CANDLE 13.2 | F11: 55 | G11: 39.99 | H11: 0 | I11: 0.99 | J11: 40.98 | K11: =#REF!-resources!$B$14 -> #REF!
A12: 2024-08-05 | B12: 859 | C12: 19 | D12: 16255 | E12: LD.CANDLE 13.2 | F12: 55 | G12: 37.33 | H12: 0 | I12: 0.84 | J12: 38.17 | K12: =#REF!-resources!$B$14 -> #REF!
A13: 2024-07-12 | B13: 283 | C13: 19 | D13: 16255 | E13: LD.CANDLE 13.2 | F13: 54 | G13: 73.52 | H13: 0 | I13: 1.23 | J13: 74.75 | K13: =#REF!-resources!$B$14 -> #REF!
... A1489: 2024-08-30 | B1489: 1446 | C1489: 6 | D1489: 16255 | E1489: LD.CANDLE 13.2 | F1489: 20 | G1489: 42.82 | H1489: 0.4 | I1489: 0.88 | J1489: 44.1 | K1489: =#REF!-resources!$B$14 -> #REF!

Sheet load
A1: year | B1: actual | C1: extreme | D1: normal | E1: cable1 | F1: cable2 | G1: cable_all | H1: battery | I1: diesel | J1: diecab | K1: diecabbat | L1: diecabup | M1: extreme_90 | N1: nm1_existing
A2: 2019 | B2: =annual_peaks_estimated_data!E15 -> 50.599078 | C2: =annual_peaks_estimated_data!D15 -> 51.72772 | D2: =annual_peaks_estimated_data!B15 -> 46.747247 | E2: 36 | F2: 38 | G2: 74 | H2: 6 | I2: 15 | J2: =I2+G2 -> 89 | K2: =J2+H2 -> 95 | L2: =I2+results!E4 -> 89 | M2: 49.42904 | N2: =E2+F2+H2+I2-MAX(E2,F2,H2,I2) -> 57
A3: 2020 | B3: =annual_peaks_estimated_data!E16 -> 52.073733 | C3: =annual_peaks_estimated_data!D16 -> 55.941967 | D3: =annual_peaks_estimated_data!B16 -> 48.088143 | E3: 36 | F3: 38 | G3: 74 | H3: 6 | I3: 15 | J3: =I3+G3 -> 89 | K3: =J3+H3 -> 95 | L3: =I3+results!E5 -> 89 | M3: 53.834843 | N3: =E3+F3+H3+I3-MAX(E3,F3,H3,I3) -> 57
A4: 2021 | B4: =annual_peaks_estimated_data!E17 -> 52.81106 | C4: =annual_peaks_estimated_data!D17 -> 56.133523 | D4: =annual_peaks_estimated_data!B17 -> 51.15305 | E4: 36 | F4: 38 | G4: 74 | H4: 6 | I4: 15 | J4: =I4+G4 -> 89 | K4: =J4+H4 -> 95 | L4: =I4+results!E6 -> 89 | M4: 54.60107 | N4: =E4+F4+H4+I4-MAX(E4,F4,H4,I4) -> 57
A5: 2022 | B5: =annual_peaks_estimated_data!E18 -> 58.2 | C5: =annual_peaks_estimated_data!D18 -> 59.19843 | D5: =annual_peaks_estimated_data!B18 -> 51.536163 | E5: 36 | F5: 38 | G5: 74 | H5: 6 | I5: 15 | J5: =I5+G5 -> 89 | K5: =J5+H5 -> 95 | L5: =I5+results!E7 -> 89 | M5: 56.708193 | N5: =E5+F5+H5+I5-MAX(E5,F5,H5,I5) -> 57
A6: 2023 | B6: =annual_peaks_estimated_data!E19 -> 0 | C6: =annual_peaks_estimated_data!D19 -> 60.156213 | D6: =annual_peaks_estimated_data!B19 -> 52.493947 | E6: 36 | F6: 38 | G6: 74 | H6: 6 | I6: 15 | J6: =I6+G6 -> 89 | K6: =J6+H6 -> 95 | L6: =I6+results!E8 -> 89 | M6: 58.240647 | N6: =E6+F6+H6+I6-MAX(E6,F6,H6,I6) -> 57
A7: 2024 | B7: =annual_peaks_estimated_data!E20 -> 0 | C7: =annual_peaks_estimated_data!D20 -> 61.688667 | D7: =annual_peaks_estimated_data!B20 -> 53.45173 | E7: 36 | F7: 38 | G7: 74 | H7: 6 | I7: 15 | J7: =I7+G7 -> 89 | K7: =J7+H7 -> 95 | L7: =I7+results!E9 -> 89 | M7: 59.581543 | N7: =E7+F7+H7+I7-MAX(E7,F7,H7,I7) -> 57
A8: 2025 | B8: =annual_peaks_estimated_data!E21 -> 0 | C8: =annual_peaks_estimated_data!D21 -> 62.454893 | D8: =annual_peaks_estimated_data!B21 -> 54.409513 | E8: 36 | F8: 38 | G8: 74 | H8: 6 | I8: 15 | J8: =I8+G8 -> 89 | K8: =J8+H8 -> 95 | L8: =I8+results!E10 -> 89 | M8: 60.34777 | N8: =E8+F8+H8+I8-MAX(E8,F8,H8,I8) -> 57
A9: 2026 | B9: =annual_peaks_estimated_data!E22 -> 0 | C9: =annual_peaks_estimated_data!D22 -> 63.987347 | D9: =annual_peaks_estimated_data!B22 -> 55.558853 | E9: 36 | F9: 38 | G9: 74 | H9: 6 | I9: 15 | J9: =I9+G9 -> 89 | K9: =J9+H9 -> 95 | L9: =I9+results!E11 -> 89 | M9: 61.880223 | N9: =E9+F9+H9+I9-MAX(E9,F9,H9,I9) -> 57
A10: 2027 | B10: =annual_peaks_estimated_data!E23 -> 0 | C10: =annual_peaks_estimated_data!D23 -> 65.328243 | D10: =annual_peaks_estimated_data!B23 -> 56.89975 | E10: 36 | F10: 38 | G10: 74 | H10: 6 | I10: 15 | J10: =I10+G10 -> 89 | K10: =J10+H10 -> 95 | L10: =I10+results!E12 -> 89 | M10: 63.22112 | N10: =E10+F10+H10+I10-MAX(E10,F10,H10,I10) -> 57
A11: 2028 | B11: =annual_peaks_estimated_data!E24 -> 0 | C11: =annual_peaks_estimated_data!D24 -> 66.66914 | D11: =annual_peaks_estimated_data!B24 -> 58.04909 | E11: 36 | F11: 38 | G11: 74 | H11: 6 | I11: 15 | J11: =I11+G11 -> 89 | K11: =J11+H11 -> 95 | L11: =I11+results!E13 -> 89 | M11: 64.562017 | N11: =E11+F11+H11+I11-MAX(E11,F11,H11,I11) -> 57
A12: 2029 | B12: =annual_peaks_estimated_data!E25 -> 0 | C12: =annual_peaks_estimated_data!D25 -> 68.201593 | D12: =annual_peaks_estimated_data!B25 -> 59.389987 | E12: 36 | F12: 38 | G12: 74 | H12: 6 | I12: 15 | J12: =I12+G12 -> 89 | K12: =J12+H12 -> 95 | L12: =I12+results!E14 -> 89 | M12: 66.09447 | N12: =E12+F12+H12+I12-MAX(E12,F12,H12,I12) -> 57
A13: 2030 | B13: =annual_peaks_estimated_data!E26 -> 0 | C13: =annual_peaks_estimated_data!D26 -> 70.11716 | D13: =annual_peaks_estimated_data!B26 -> 60.730883 | E13: 36 | F13: 38 | G13: 74 | H13: 6 | I13: 15 | J13: =I13+G13 -> 89 | K13: =J13+H13 -> 95 | L13: =I13+results!E15 -> 89 | M13: 67.626923 | N13: =E13+F13+H13+I13-MAX(E13,F13,H13,I13) -> 57
... A33: 2050 | B33: =annual_peaks_estimated_data!E46 -> 0 | C33: =annual_peaks_estimated_data!D46 -> 98.084433 | D33: =annual_peaks_estimated_data!B46 -> 85.824807 | E33: 0 | F33: 0 | G33: 0 | H33: 0 | I33: 15 | J33: =I33+G33 -> 15 | K33: =J33+H33 -> 15 | L33: =I33+results!E35 -> 135 | M33: 95.40264 | N33: =E33+F33+H33+I33-MAX(E33,F33,H33,I33) -> 0

Sheet resources
A1: Underline cables | E1: BESS (20 year shelf life) | I1: Interconnected Solar | K1: Generator | M1: Sources | N1: https://nantucket.bluedotliving.com/2024/06/28/field-note-electric-power-on-nantucket/
A2: Capacity (MW) | B2: Installed | C2: Payback by | D2: Cost | E2: Power (MW) | F2: Energy (MWh) | G2: Installed | I2: Power (MW) | K2: Power (MW) | N2: https://www.utilitydive.com/news/there-once-was-an-energy-storage-system-on-nantucket/513650/
A3: 36 | B3: 1996 | C3: 2026 | E3: 6 | F3: 48 | G3: 2019 | I3: 5 | K3: 15 | N3: https://nantucket.bluedotliving.com/2024/06/28/field-note-a-better-energy-future-for-nantucket/
A4: 38 | B4: 2006 | C4: 2026 | D4: 41 | N4: https://www.nantucket-ma.gov/997/Beat-the-Peak-Initiative
N5: https://www.nantucket-ma.gov/DocumentCenter/View/18095/Nantucket_Inquirer_and_Mirror_20171207_A04?bidId=
A6: Cost range of a third subsea cable (million USD) to local ratepayers | G6: Operating strategy: | N6: https://www.nantucket-ma.gov/DocumentCenter/View/16013/Residential-Aggregation-Proposal-Summary-to-Nantucket-5-18-17?bidId=
A7: 100 | B7: 175 | D7: on the Nantucket MA website | G7: Charge battery from generator in case of cable failure, one-day of fuel for generator | N7: https://www.nationalgridus.com/media/construction-projects/pdfs/ma/islandready/islandready-fact-sheet_august-2019-new.pdf
A8: 75 | B8: 100 | D8: in 2017 | N8: https://www.utilitydive.com/news/Tesla-national-grid-battery-energy-storage-8hour-long-duration-diesel-generation-system-nantucket/564428/
G9: Cost for battery and 15 MW diesel turbine and upgrade to power control house (million) | N9: https://www.wbur.org/news/2019/10/08/nantucket-energy-storage-lithium-ion-giant-battery
A10: Goal delay the need for a third cable by 10 years | G10: 81 | H10: who paid for this? | N10: https://www.power-grid.com/der-grid-edge/peaks-and-valleys-how-national-grids-non-wires-alternative-ensures-delivery-to-nantucket-island/
A11: Bet on improving battery technology and other solutions | N11: https://www.iso-ne.com/static-assets/documents/100003/ems-color-system-diagram.pdf
G12: PNNL was looking at other applications, frequency regulation for example | N12: https://www.vineyardwind.com/map
A13: Total firm capacity (MW) | B13: =A3+A4+E3+K3 -> 95 | N13: https://nantucketcurrent.com/news/undersea-electric-cable-to-nantucket-back-online
A14: N-1 | B14: =B13-MAX(A3,A4,E3,K3) -> 57 | N14: https://nantucketcurrent.com/news/one-of-the-two-undersea-cables-that-provide-electricity-to-nantucket-is-broken-down
A16: Subsea cable lifetime | B16: 40 | C16: years | M16: Load data: | N16: https://www.iso-ne.com/isoexpress/web/reports/load-and-demand/-/tree/nodal-load-wgts-archive
M17: Zone 6 for SEMASS
A18: Battery lifetime | B18: 20 | C18: years | D18: https://energystorage.pnnl.gov/pdf/PNNL-28941.pdf
M19: Contact | N19: Lauren Sinatra, Town of Nantucket Energy Department
M22: Vineyard Wind Fund | N22: https://www.nantucket-ma.gov/136/Energy-Office
B24: https://vineyardgazette.com/news/2024/10/30/eversource-looks-meet-growing-energy-needs | M24: Town energy use | N24: https://www.nantucket-ma.gov/DocumentCenter/View/46848/Criterion-3-Energy-Reduction-Plan?bidId=
B25: https://www.mvtimes.com/2021/07/19/power-outages-caused-undersea-cable-failure/
A26: MV submarine cables | B26: https://www.mvtimes.com/2023/11/06/eversource-submarine-cable-projects-works/
A27: Cable # | B27: Installed | C27: Type | D27: Faulty | E27: Decommissioned | F27: Lifetime (years)
A28: 99 | B28: 2013 | C28: buried
A29: 75 | C29: direct-lay
A30: 97 | C30: direct-lay
A31: 91 | B31: 1986 | C31: direct-lay | D31: 2021 | E31: 2026 | F31: =E31-B31 -> 40

Sheet projections
A1: Year | B1: Actual Load (MW) | C1: Projected Extreme Peak Load (MW) | D1: Projected Normal Peak Load (MW) | E1: Subsea cap (MW) | F1: Subsea cable 1 (MW) | G1: Subsea Cable 2 (MW) | H1: Battery (MW) | I1: Diesel (MW) | J1: Peak Margin Extreme (MW) | K1: N-1 Margin Extreme (MW) | L1: Peak Margin Normal (MW) | M1: N-1 Marginal Normal (MW)
A2: 2019 | B2: =annual_peaks_estimated_data!E15 -> 50.599078 | C2: =annual_peaks_estimated_data!D15 -> 51.72772 | D2: =annual_peaks_estimated_data!B15 -> 46.747247 | E2: =F2+G2 -> 74 | F2: 36 | G2: 38 | H2: 6 | I2: 15 | J2: =SUM(F2:I2)-C2 -> 43.27228 | K2: =SUM(F2:I2)-MAX(F2:I2)-C2 -> 5.2722799 | L2: =SUM(F2:I2)-D2 -> 48.252753 | M2: =SUM(F2:I2)-MAX(F2:I2)-D2 -> 10.252753
A3: 2020 | B3: =annual_peaks_estimated_data!E16 -> 52.073733 | C3: =annual_peaks_estimated_data!D16 -> 55.941967 | D3: =annual_peaks_estimated_data!B16 -> 48.088143 | E3: =F3+G3 -> 74 | F3: 36 | G3: 38 | H3: 6 | I3: 15 | J3: =SUM(F3:I3)-C3 -> 39.058033 | K3: =SUM(F3:I3)-MAX(F3:I3)-C3 -> 1.0580333 | L3: =SUM(F3:I3)-D3 -> 46.911857 | M3: =SUM(F3:I3)-MAX(F3:I3)-D3 -> 8.9118566
A4: 2021 | B4: =annual_peaks_estimated_data!E17 -> 52.81106 | C4: =annual_peaks_estimated_data!D17 -> 56.133523 | D4: =annual_peaks_estimated_data!B17 -> 51.15305 | E4: =F4+G4 -> 74 | F4: 36 | G4: 38 | H4: 6 | I4: 15 | J4: =SUM(F4:I4)-C4 -> 38.866477 | K4: =SUM(F4:I4)-MAX(F4:I4)-C4 -> 0.86647661 | L4: =SUM(F4:I4)-D4 -> 43.84695 | M4: =SUM(F4:I4)-MAX(F4:I4)-D4 -> 5.8469499
A5: 2022 | B5: =annual_peaks_estimated_data!E18 -> 58.2 | C5: =annual_peaks_estimated_data!D18 -> 59.19843 | D5: =annual_peaks_estimated_data!B18 -> 51.536163 | E5: =F5+G5 -> 74 | F5: 36 | G5: 38 | H5: 6 | I5: 15 | J5: =SUM(F5:I5)-C5 -> 35.80157 | K5: =SUM(F5:I5)-MAX(F5:I5)-C5 -> -2.1984301 | L5: =SUM(F5:I5)-D5 -> 43.463837 | M5: =SUM(F5:I5)-MAX(F5:I5)-D5 -> 5.4638366
A6: 2023 | B6: =annual_peaks_estimated_data!E19 -> 0 | C6: =annual_peaks_estimated_data!D19 -> 60.156213 | D6: =annual_peaks_estimated_data!B19 -> 52.493947 | E6: =F6+G6 -> 74 | F6: 36 | G6: 38 | H6: 6 | I6: 15 | J6: =SUM(F6:I6)-C6 -> 34.843787 | K6: =SUM(F6:I6)-MAX(F6:I6)-C6 -> -3.1562134 | L6: =SUM(F6:I6)-D6 -> 42.506053 | M6: =SUM(F6:I6)-MAX(F6:I6)-D6 -> 4.5060533
A7: 2024 | B7: =annual_peaks_estimated_data!E20 -> 0 | C7: =annual_peaks_estimated_data!D20 -> 61.688667 | D7: =annual_peaks_estimated_data!B20 -> 53.45173 | E7: =F7+G7 -> 74 | F7: 36 | G7: 38 | H7: 6 | I7: 15 | J7: =SUM(F7:I7)-C7 -> 33.311333 | K7: =SUM(F7:I7)-MAX(F7:I7)-C7 -> -4.6886667 | L7: =SUM(F7:I7)-D7 -> 41.54827 | M7: =SUM(F7:I7)-MAX(F7:I7)-D7 -> 3.5482699
A8: 2025 | B8: =annual_peaks_estimated_data!E21 -> 0 | C8: =annual_peaks_estimated_data!D21 -> 62.454893 | D8: =annual_peaks_estimated_data!B21 -> 54.409513 | E8: =F8+G8 -> 74 | F8: 36 | G8: 38 | H8: 6 | I8: 15 | J8: =SUM(F8:I8)-C8 -> 32.545107 | K8: =SUM(F8:I8)-MAX(F8:I8)-C8 -> -5.4548934 | L8: =SUM(F8:I8)-D8 -> 40.590487 | M8: =SUM(F8:I8)-MAX(F8:I8)-D8 -> 2.5904866
A9: 2026 | B9: =annual_peaks_estimated_data!E22 -> 0 | C9: =annual_peaks_estimated_data!D22 -> 63.987347 | D9: =annual_peaks_estimated_data!B22 -> 55.558853 | E9: =F9+G9 -> 74 | F9: 36 | G9: 38 | H9: 6 | I9: 15 | J9: =SUM(F9:I9)-C9 -> 31.012653 | K9: =SUM(F9:I9)-MAX(F9:I9)-C9 -> -6.9873467 | L9: =SUM(F9:I9)-D9 -> 39.441147 | M9: =SUM(F9:I9)-MAX(F9:I9)-D9 -> 1.4411466
A10: 2027 | B10: =annual_peaks_estimated_data!E23 -> 0 | C10: =annual_peaks_estimated_data!D23 -> 65.328243 | D10: =annual_peaks_estimated_data!B23 -> 56.89975 | E10: =F10+G10 -> 74 | F10: 36 | G10: 38 | H10: 6 | I10: 15 | J10: =SUM(F10:I10)-C10 -> 29.671757 | K10: =SUM(F10:I10)-MAX(F10:I10)-C10 -> -8.3282434 | L10: =SUM(F10:I10)-D10 -> 38.10025 | M10: =SUM(F10:I10)-MAX(F10:I10)-D10 -> 0.10024994
A11: 2028 | B11: =annual_peaks_estimated_data!E24 -> 0 | C11: =annual_peaks_estimated_data!D24 -> 66.66914 | D11: =annual_peaks_estimated_data!B24 -> 58.04909 | E11: =F11+G11 -> 74 | F11: 36 | G11: 38 | H11: 6 | I11: 15 | J11: =SUM(F11:I11)-C11 -> 28.33086 | K11: =SUM(F11:I11)-MAX(F11:I11)-C11 -> -9.66914 | L11: =SUM(F11:I11)-D11 -> 36.95091 | M11: =SUM(F11:I11)-MAX(F11:I11)-D11 -> -1.0490901
A12: 2029 | B12: =annual_peaks_estimated_data!E25 -> 0 | C12: =annual_peaks_estimated_data!D25 -> 68.201593 | D12: =annual_peaks_estimated_data!B25 -> 59.389987 | E12: =F12+G12 -> 74 | F12: 36 | G12: 38 | H12: 6 | I12: 15 | J12: =SUM(F12:I12)-C12 -> 26.798407 | K12: =SUM(F12:I12)-MAX(F12:I12)-C12 -> -11.201593 | L12: =SUM(F12:I12)-D12 -> 35.610013 | M12: =SUM(F12:I12)-MAX(F12:I12)-D12 -> -2.3899867
A13: 2030 | B13: =annual_peaks_estimated_data!E26 -> 0 | C13: =annual_peaks_estimated_data!D26 -> 70.11716 | D13: =annual_peaks_estimated_data!B26 -> 60.730883 | E13: =F13+G13 -> 74 | F13: 36 | G13: 38 | H13: 6 | I13: 15 | J13: =SUM(F13:I13)-C13 -> 24.88284 | K13: =SUM(F13:I13)-MAX(F13:I13)-C13 -> -13.11716 | L13: =SUM(F13:I13)-D13 -> 34.269117 | M13: =SUM(F13:I13)-MAX(F13:I13)-D13 -> -3.7308834
... A33: 2050 | B33: =annual_peaks_estimated_data!E46 -> 0 | C33: =annual_peaks_estimated_data!D46 -> 98.084433 | D33: =annual_peaks_estimated_data!B46 -> 85.824807 | E33: =F33+G33 -> 0 | F33: 0 | G33: 0 | H33: 0 | I33: 15 | J33: =SUM(F33:I33)-C33 -> -83.084433 | K33: =SUM(F33:I33)-MAX(F33:I33)-C33 -> -98.084433 | L33: =SUM(F33:I33)-D33 -> -70.824807 | M33: =SUM(F33:I33)-MAX(F33:I33)-D33 -> -85.824807

Sheet data_csv
A1: year | B1: gen_margin | C1: load_margin | D1: cost | E1: lifetime | F1: nominal cost | G1: battery nominal cost per MW | H1: battery lifetime | I1: battery prorated cost
A2: 2019 | B2: 43.27228 | C2: =-B2 -> -43.27228 | D2: =MIN(1, ($A$33-$A2+1)/$E$2)*$F$2 -> 160 | E2: 40 | F2: 200 | G2: =1.5*8 -> 12 | H2: 20 | I2: =MIN(1, ($A$33-$A2+1)/$H$2)*$G2 -> 12
A3: 2020 | B3: 39.058033 | C3: =-B3 -> -39.058033 | D3: =MIN(1, ($A$33-$A3+1)/$E$2)*$F$2 -> 155 | G3: =(G$2-G$33)*(A$33-A3)/(A$33-A$2)+G$33 -> 11.677419 | I3: =MIN(1, ($A$33-$A3+1)/$H$2)*$G3 -> 11.677419
A4: 2021 | B4: 38.866477 | C4: =-B4 -> -38.866477 | D4: =MIN(1, ($A$33-$A4+1)/$E$2)*$F$2 -> 150 | G4: =(G$2-G$33)*(A$33-A4)/(A$33-A$2)+G$33 -> 11.354839 | I4: =MIN(1, ($A$33-$A4+1)/$H$2)*$G4 -> 11.354839
A5: 2022 | B5: 35.80157 | C5: =-B5 -> -35.80157 | D5: =MIN(1, ($A$33-$A5+1)/$E$2)*$F$2 -> 145 | G5: =(G$2-G$33)*(A$33-A5)/(A$33-A$2)+G$33 -> 11.032258 | I5: =MIN(1, ($A$33-$A5+1)/$H$2)*$G5 -> 11.032258
A6: 2023 | B6: 34.843787 | C6: =-B6 -> -34.843787 | D6: =MIN(1, ($A$33-$A6+1)/$E$2)*$F$2 -> 140 | G6: =(G$2-G$33)*(A$33-A6)/(A$33-A$2)+G$33 -> 10.709677 | I6: =MIN(1, ($A$33-$A6+1)/$H$2)*$G6 -> 10.709677
A7: 2024 | B7: 33.311333 | C7: =-B7 -> -33.311333 | D7: =MIN(1, ($A$33-$A7+1)/$E$2)*$F$2 -> 135 | G7: =(G$2-G$33)*(A$33-A7)/(A$33-A$2)+G$33 -> 10.387097 | I7: =MIN(1, ($A$33-$A7+1)/$H$2)*$G7 -> 10.387097
A8: 2025 | B8: 32.545107 | C8: =-B8 -> -32.545107 | D8: =MIN(1, ($A$33-$A8+1)/$E$2)*$F$2 -> 130 | G8: =(G$2-G$33)*(A$33-A8)/(A$33-A$2)+G$33 -> 10.064516 | I8: =MIN(1, ($A$33-$A8+1)/$H$2)*$G8 -> 10.064516
A9: 2026 | B9: 31.012653 | C9: =-B9 -> -31.012653 | D9: =MIN(1, ($A$33-$A9+1)/$E$2)*$F$2 -> 125 | G9: =(G$2-G$33)*(A$33-A9)/(A$33-A$2)+G$33 -> 9.7419355 | I9: =MIN(1, ($A$33-$A9+1)/$H$2)*$G9 -> 9.7419355
A10: 2027 | B10: 29.671757 | C10: =-B10 -> -29.671757 | D10: =MIN(1, ($A$33-$A10+1)/$E$2)*$F$2 -> 120 | G10: =(G$2-G$33)*(A$33-A10)/(A$33-A$2)+G$33 -> 9.4193548 | I10: =MIN(1, ($A$33-$A10+1)/$H$2)*$G10 -> 9.4193548
A11: 2028 | B11: 28.33086 | C11: =-B11 -> -28.33086 | D11: =MIN(1, ($A$33-$A11+1)/$E$2)*$F$2 -> 115 | G11: =(G$2-G$33)*(A$33-A11)/(A$33-A$2)+G$33 -> 9.0967742 | I11: =MIN(1, ($A$33-$A11+1)/$H$2)*$G11 -> 9.0967742
A12: 2029 | B12: 26.798407 | C12: =-B12 -> -26.798407 | D12: =MIN(1, ($A$33-$A12+1)/$E$2)*$F$2 -> 110 | G12: =(G$2-G$33)*(A$33-A12)/(A$33-A$2)+G$33 -> 8.7741935 | I12: =MIN(1, ($A$33-$A12+1)/$H$2)*$G12 -> 8.7741935
A13: 2030 | B13: 24.88284 | C13: =-B13 -> -24.88284 | D13: =MIN(1, ($A$33-$A13+1)/$E$2)*$F$2 -> 105 | G13: =(G$2-G$33)*(A$33-A13)/(A$33-A$2)+G$33 -> 8.4516129 | I13: =MIN(1, ($A$33-$A13+1)/$H$2)*$G13 -> 8.4516129
A14: 2031 | B14: 23.350387 | C14: =-B14 -> -23.350387 | D14: =MIN(1, ($A$33-$A14+1)/$E$2)*$F$2 -> 100 | G14: =(G$2-G$33)*(A$33-A14)/(A$33-A$2)+G$33 -> 8.1290323 | I14: =MIN(1, ($A$33-$A14+1)/$H$2)*$G14 -> 8.1290323
... A32: 2049 | B32: -82.318207 | C32: =-B32 -> 82.318207 | D32: =MIN(1, ($A$33-$A32+1)/$E$2)*$F$2 -> 10 | G32: =(G$2-G$33)*(A$33-A32)/(A$33-A$2)+G$33 -> 2.3225806 | I32: =MIN(1, ($A$33-$A32+1)/$H$2)*$G32 -> 0.23225806
A33: 2050 | B33: -83.084433 | C33: =-B33 -> 83.084433 | D33: =MIN(1, ($A$33-$A33+1)/$E$2)*$F$2 -> 5 | G33: =0.25*8 -> 2 | I33: =MIN(1, ($A$33-$A33+1)/$H$2)*$G33 -> 0.1

Sheet jp_data
A1: Backup diesel left out for now
A3: Subsea cable cost | H3: Battery cost | P3: Peak load | V3: Value of lost load
A4: 200 | B4: million for | C4: 40 | D4: MW for | E4: 40 | F4: years | H4: 81 | I4: million for | J4: 6 | K4: MW with 48MWh and 15MW backup diesel for | V4: 2500 | W4: $/MWh
H5: assume | I5: 72 | J5: million for battery only for | M5: 20 | N5: years | P5: scale linearly, in reality modes will shift
A6: considered mature technology, no expected cost savings | I6: 2 | J6: million per MWh in 2050, i.e, 0.25 million per MWh | V6: Electricity price
P7: 15 | Q7: days per year | V7: 50 | W7: $/MWh
A8: for new installations | H8: for new installations | K8: decrease geometrically thanks to technology improvement | P8: in reality, the number of peak load days will increase | V8: flat, in reality the price will fluctuate throughout the day
A9: min cap | B9: 40 | H9: min cap | I9: 1 | K9: possibly with uncertainty
A10: max cap | B10: 40 | H10: max cap | I10: 10
A13: Per MW cost if installed in | D13: Existing capacity in | H13: Per MW cost if installed in | K13: Prorated cost | M13: Existing capacity in | P13: Year/Hour | Q13: 1 | R13: 2 | S13: 3 | T13: 4 | U13: 5 | V13: 6 | W13: 7 | X13: 8 | Y13: 9 | Z13: 10 | AA13: 11 | AB13: 12 | AC13: 13 | AD13: 14 | AE13: 15 | AF13: 16 | AG13: 17 | AH13: 18 | AI13: 19 | AJ13: 20 | AK13: 21 | AL13: 22 | AM13: 23 | AN13: 24
A14: 2025 | B14: =A$4/C$4/E$4*COUNT(A14:A$39) -> 3.25 | D14: 74 | H14: 2019 | I14: =I5/J4 -> 12 | K14: =I14/M$5*MIN(COUNT(H14:H45), M$5) -> 12 | M14: 6 | P14: 2024 | Q14: 38 | R14: 38 | S14: 35 | T14: 33 | U14: 32 | V14: 32 | W14: 32 | X14: 36 | Y14: 41 | Z14: 45 | AA14: 46 | AB14: 47 | AC14: 49 | AD14: 50 | AE14: 51 | AF14: 53 | AG14: 54 | AH14: 57 | AI14: 57 | AJ14: 55 | AK14: 53 | AL14: 51 | AM14: 48 | AN14: 45
A15: 2026 | B15: =A$4/C$4/E$4*COUNT(A15:A$39) -> 3.125 | D15: 74 | H15: 2020 | I15: =I$14*(I$45/I$14)^((H15-H$14)/(H$45-H$14)) -> 10.591261 | K15: =I15/M$5*MIN(COUNT(H15:H45), M$5) -> 10.591261 | M15: 6 | P15: 2025 | Q15: =(Q$40-Q$14)/(P$40-P$14)*(P15-P$14)+Q$14 -> 39.051282 | R15: =(R$40-R$14)/(Q$40-Q$14)*(Q15-Q$14)+R$14 -> 39.051282 | S15: =(S$40-S$14)/(R$40-R$14)*(R15-R$14)+S$14 -> 35.968286 | T15: =(T$40-T$14)/(S$40-S$14)*(S15-S$14)+T$14 -> 33.912955 | U15: =(U$40-U$14)/(T$40-T$14)*(T15-T$14)+U$14 -> 32.88529 | V15: =(V$40-V$14)/(U$40-U$14)*(U15-U$14)+V$14 -> 32.88529 | W15: =(W$40-W$14)/(V$40-V$14)*(V15-V$14)+W$14 -> 32.88529 | X15: =(X$40-X$14)/(W$40-W$14)*(W15-W$14)+X$14 -> 36.995951 | ... AN15: =(AN$40-AN$14)/(AM$40-AM$14)*(AM15-AM$14)+AN$14 -> 46.244939
A16: 2027 | B16: =A$4/C$4/E$4*COUNT(A16:A$39) -> 3 | D16: 74 | H16: 2021 | I16: =I$14*(I$45/I$14)^((H16-H$14)/(H$45-H$14)) -> 9.3479002 | K16: =I16/M$5*MIN(COUNT(H16:H45), M$5) -> 9.3479002 | M16: 6 | P16: 2026 | Q16: =(Q$40-Q$14)/(P$40-P$14)*(P16-P$14)+Q$14 -> 40.102564 | R16: =(R$40-R$14)/(Q$40-Q$14)*(Q16-Q$14)+R$14 -> 40.102564 | S16: =(S$40-S$14)/(R$40-R$14)*(R16-R$14)+S$14 -> 36.936572 | T16: =(T$40-T$14)/(S$40-S$14)*(S16-S$14)+T$14 -> 34.825911 | U16: =(U$40-U$14)/(T$40-T$14)*(T16-T$14)+U$14 -> 33.77058 | V16: =(V$40-V$14)/(U$40-U$14)*(U16-U$14)+V$14 -> 33.77058 | W16: =(W$40-W$14)/(V$40-V$14)*(V16-V$14)+W$14 -> 33.77058 | X16: =(X$40-X$14)/(W$40-W$14)*(W16-W$14)+X$14 -> 37.991903 | ... AN16: =(AN$40-AN$14)/(AM$40-AM$14)*(AM16-AM$14)+AN$14 -> 47.489879
A17: 2028 | B17: =A$4/C$4/E$4*COUNT(A17:A$39) -> 2.875 | D17: 74 | H17: 2022 | I17: =I$14*(I$45/I$14)^((H17-H$14)/(H$45-H$14)) -> 8.250504 | K17: =I17/M$5*MIN(COUNT(H17:H45), M$5) -> 8.250504 | M17: 6 | P17: 2027 | Q17: =(Q$40-Q$14)/(P$40-P$14)*(P17-P$14)+Q$14 -> 41.153846 | R17: =(R$40-R$14)/(Q$40-Q$14)*(Q17-Q$14)+R$14 -> 41.153846 | S17: =(S$40-S$14)/(R$40-R$14)*(R17-R$14)+S$14 -> 37.904858 | T17: =(T$40-T$14)/(S$40-S$14)*(S17-S$14)+T$14 -> 35.738866 | U17: =(U$40-U$14)/(T$40-T$14)*(T17-T$14)+U$14 -> 34.65587 | V17: =(V$40-V$14)/(U$40-U$14)*(U17-U$14)+V$14 -> 34.65587 | W17: =(W$40-W$14)/(V$40-V$14)*(V17-V$14)+W$14 -> 34.65587 | X17: =(X$40-X$14)/(W$40-W$14)*(W17-W$14)+X$14 -> 38.987854 | ... AN17: =(AN$40-AN$14)/(AM$40-AM$14)*(AM17-AM$14)+AN$14 -> 48.734818
A18: 2029 | B18: =A$4/C$4/E$4*COUNT(A18:A$39) -> 2.75 | D18: 74 | H18: 2023 | I18: =I$14*(I$45/I$14)^((H18-H$14)/(H$45-H$14)) -> 7.2819366 | K18: =I18/M$5*MIN(COUNT(H18:H45), M$5) -> 7.2819366 | M18: 6 | P18: 2028 | Q18: =(Q$40-Q$14)/(P$40-P$14)*(P18-P$14)+Q$14 -> 42.205128 | R18: =(R$40-R$14)/(Q$40-Q$14)*(Q18-Q$14)+R$14 -> 42.205128 | S18: =(S$40-S$14)/(R$40-R$14)*(R18-R$14)+S$14 -> 38.873144 | T18: =(T$40-T$14)/(S$40-S$14)*(S18-S$14)+T$14 -> 36.651822 | U18: =(U$40-U$14)/(T$40-T$14)*(T18-T$14)+U$14 -> 35.541161 | V18: =(V$40-V$14)/(U$40-U$14)*(U18-U$14)+V$14 -> 35.541161 | W18: =(W$40-W$14)/(V$40-V$14)*(V18-V$14)+W$14 -> 35.541161 | X18: =(X$40-X$14)/(W$40-W$14)*(W18-W$14)+X$14 -> 39.983806 | ... AN18: =(AN$40-AN$14)/(AM$40-AM$14)*(AM18-AM$14)+AN$14 -> 49.979757
A19: 2030 | B19: =A$4/C$4/E$4*COUNT(A19:A$39) -> 2.625 | D19: 74 | H19: 2024 | I19: =I$14*(I$45/I$14)^((H19-H$14)/(H$45-H$14)) -> 6.4270741 | K19: =I19/M$5*MIN(COUNT(H19:H45), M$5) -> 6.4270741 | M19: 6 | P19: 2029 | Q19: =(Q$40-Q$14)/(P$40-P$14)*(P19-P$14)+Q$14 -> 43.25641 | R19: =(R$40-R$14)/(Q$40-Q$14)*(Q19-Q$14)+R$14 -> 43.25641 | S19: =(S$40-S$14)/(R$40-R$14)*(R19-R$14)+S$14 -> 39.84143 | T19: =(T$40-T$14)/(S$40-S$14)*(S19-S$14)+T$14 -> 37.564777 | U19: =(U$40-U$14)/(T$40-T$14)*(T19-T$14)+U$14 -> 36.426451 | V19: =(V$40-V$14)/(U$40-U$14)*(U19-U$14)+V$14 -> 36.426451 | W19: =(W$40-W$14)/(V$40-V$14)*(V19-V$14)+W$14 -> 36.426451 | X19: =(X$40-X$14)/(W$40-W$14)*(W19-W$14)+X$14 -> 40.979757 | ... AN19: =(AN$40-AN$14)/(AM$40-AM$14)*(AM19-AM$14)+AN$14 -> 51.224696
A20: 2031 | B20: =A$4/C$4/E$4*COUNT(A20:A$39) -> 2.5 | D20: 74 | H20: 2025 | I20: =I$14*(I$45/I$14)^((H20-H$14)/(H$45-H$14)) -> 5.6725681 | K20: =I20/M$5*MIN(COUNT(H20:H46), M$5) -> 5.6725681 | M20: 6 | P20: 2030 | Q20: =(Q$40-Q$14)/(P$40-P$14)*(P20-P$14)+Q$14 -> 44.307692 | R20: =(R$40-R$14)/(Q$40-Q$14)*(Q20-Q$14)+R$14 -> 44.307692 | S20: =(S$40-S$14)/(R$40-R$14)*(R20-R$14)+S$14 -> 40.809717 | T20: =(T$40-T$14)/(S$40-S$14)*(S20-S$14)+T$14 -> 38.477733 | U20: =(U$40-U$14)/(T$40-T$14)*(T20-T$14)+U$14 -> 37.311741 | V20: =(V$40-V$14)/(U$40-U$14)*(U20-U$14)+V$14 -> 37.311741 | W20: =(W$40-W$14)/(V$40-V$14)*(V20-V$14)+W$14 -> 37.311741 | X20: =(X$40-X$14)/(W$40-W$14)*(W20-W$14)+X$14 -> 41.975709 | ... AN20: =(AN$40-AN$14)/(AM$40-AM$14)*(AM20-AM$14)+AN$14 -> 52.469636
A21: 2032 | B21: =A$4/C$4/E$4*COUNT(A21:A$39) -> 2.375 | D21: 74 | H21: 2026 | I21: =I$14*(I$45/I$14)^((H21-H$14)/(H$45-H$14)) -> 5.0066373 | K21: =I21/M$5*MIN(COUNT(H21:H47), M$5) -> 5.0066373 | M21: 6 | P21: 2031 | Q21: =(Q$40-Q$14)/(P$40-P$14)*(P21-P$14)+Q$14 -> 45.358974 | R21: =(R$40-R$14)/(Q$40-Q$14)*(Q21-Q$14)+R$14 -> 45.358974 | S21: =(S$40-S$14)/(R$40-R$14)*(R21-R$14)+S$14 -> 41.778003 | T21: =(T$40-T$14)/(S$40-S$14)*(S21-S$14)+T$14 -> 39.390688 | U21: =(U$40-U$14)/(T$40-T$14)*(T21-T$14)+U$14 -> 38.197031 | V21: =(V$40-V$14)/(U$40-U$14)*(U21-U$14)+V$14 -> 38.197031 | W21: =(W$40-W$14)/(V$40-V$14)*(V21-V$14)+W$14 -> 38.197031 | X21: =(X$40-X$14)/(W$40-W$14)*(W21-W$14)+X$14 -> 42.97166 | ... AN21: =(AN$40-AN$14)/(AM$40-AM$14)*(AM21-AM$14)+AN$14 -> 53.714575
A22: 2033 | B22: =A$4/C$4/E$4*COUNT(A22:A$39) -> 2.25 | D22: 74 | H22: 2027 | I22: =I$14*(I$45/I$14)^((H22-H$14)/(H$45-H$14)) -> 4.4188834 | K22: =I22/M$5*MIN(COUNT(H22:H48), M$5) -> 4.4188834 | M22: 6 | P22: 2032 | Q22: =(Q$40-Q$14)/(P$40-P$14)*(P22-P$14)+Q$14 -> 46.410256 | R22: =(R$40-R$14)/(Q$40-Q$14)*(Q22-Q$14)+R$14 -> 46.410256 | S22: =(S$40-S$14)/(R$40-R$14)*(R22-R$14)+S$14 -> 42.746289 | T22: =(T$40-T$14)/(S$40-S$14)*(S22-S$14)+T$14 -> 40.303644 | U22: =(U$40-U$14)/(T$40-T$14)*(T22-T$14)+U$14 -> 39.082321 | V22: =(V$40-V$14)/(U$40-U$14)*(U22-U$14)+V$14 -> 39.082321 | W22: =(W$40-W$14)/(V$40-V$14)*(V22-V$14)+W$14 -> 39.082321 | X22: =(X$40-X$14)/(W$40-W$14)*(W22-W$14)+X$14 -> 43.967611 | ... AN22: =(AN$40-AN$14)/(AM$40-AM$14)*(AM22-AM$14)+AN$14 -> 54.959514
A23: 2034 | B23: =A$4/C$4/E$4*COUNT(A23:A$39) -> 2.125 | D23: 74 | H23: 2028 | I23: =I$14*(I$45/I$14)^((H23-H$14)/(H$45-H$14)) -> 3.9001288 | K23: =I23/M$5*MIN(COUNT(H23:H49), M$5) -> 3.9001288 | M23: 6 | P23: 2033 | Q23: =(Q$40-Q$14)/(P$40-P$14)*(P23-P$14)+Q$14 -> 47.461538 | R23: =(R$40-R$14)/(Q$40-Q$14)*(Q23-Q$14)+R$14 -> 47.461538 | S23: =(S$40-S$14)/(R$40-R$14)*(R23-R$14)+S$14 -> 43.714575 | T23: =(T$40-T$14)/(S$40-S$14)*(S23-S$14)+T$14 -> 41.216599 | U23: =(U$40-U$14)/(T$40-T$14)*(T23-T$14)+U$14 -> 39.967611 | V23: =(V$40-V$14)/(U$40-U$14)*(U23-U$14)+V$14 -> 39.967611 | W23: =(W$40-W$14)/(V$40-V$14)*(V23-V$14)+W$14 -> 39.967611 | X23: =(X$40-X$14)/(W$40-W$14)*(W23-W$14)+X$14 -> 44.963563 | ... AN23: =(AN$40-AN$14)/(AM$40-AM$14)*(AM23-AM$14)+AN$14 -> 56.204453
A24: 2035 | B24: =A$4/C$4/E$4*COUNT(A24:A$39) -> 2 | D24: 74 | H24: 2029 | I24: =I$14*(I$45/I$14)^((H24-H$14)/(H$45-H$14)) -> 3.4422734 | K24: =I24/M$5*MIN(COUNT(H24:H50), M$5) -> 3.4422734 | M24: 6 | P24: 2034 | Q24: =(Q$40-Q$14)/(P$40-P$14)*(P24-P$14)+Q$14 -> 48.512821 | R24: =(R$40-R$14)/(Q$40-Q$14)*(Q24-Q$14)+R$14 -> 48.512821 | S24: =(S$40-S$14)/(R$40-R$14)*(R24-R$14)+S$14 -> 44.682861 | T24: =(T$40-T$14)/(S$40-S$14)*(S24-S$14)+T$14 -> 42.129555 | U24: =(U$40-U$14)/(T$40-T$14)*(T24-T$14)+U$14 -> 40.852901 | V24: =(V$40-V$14)/(U$40-U$14)*(U24-U$14)+V$14 -> 40.852901 | W24: =(W$40-W$14)/(V$40-V$14)*(V24-V$14)+W$14 -> 40.852901 | X24: =(X$40-X$14)/(W$40-W$14)*(W24-W$14)+X$14 -> 45.959514 | ... AN24: =(AN$40-AN$14)/(AM$40-AM$14)*(AM24-AM$14)+AN$14 -> 57.449393
A25: 2036 | B25: =A$4/C$4/E$4*COUNT(A25:A$39) -> 1.875 | D25: 74 | H25: 2030 | I25: =I$14*(I$45/I$14)^((H25-H$14)/(H$45-H$14)) -> 3.0381679 | K25: =I25/M$5*MIN(COUNT(H25:H51), M$5) -> 3.0381679 | M25: 6 | P25: 2035 | Q25: =(Q$40-Q$14)/(P$40-P$14)*(P25-P$14)+Q$14 -> 49.564103 | R25: =(R$40-R$14)/(Q$40-Q$14)*(Q25-Q$14)+R$14 -> 49.564103 | S25: =(S$40-S$14)/(R$40-R$14)*(R25-R$14)+S$14 -> 45.651147 | T25: =(T$40-T$14)/(S$40-S$14)*(S25-S$14)+T$14 -> 43.04251 | U25: =(U$40-U$14)/(T$40-T$14)*(T25-T$14)+U$14 -> 41.738192 | V25: =(V$40-V$14)/(U$40-U$14)*(U25-U$14)+V$14 -> 41.738192 | W25: =(W$40-W$14)/(V$40-V$14)*(V25-V$14)+W$14 -> 41.738192 | X25: =(X$40-X$14)/(W$40-W$14)*(W25-W$14)+X$14 -> 46.955466 | ... AN25: =(AN$40-AN$14)/(AM$40-AM$14)*(AM25-AM$14)+AN$14 -> 58.694332
A26: 2037 | B26: =A$4/C$4/E$4*COUNT(A26:A$39) -> 1.75 | D26: 38 | H26: 2031 | I26: =I$14*(I$45/I$14)^((H26-H$14)/(H$45-H$14)) -> 2.6815024 | K26: =I26/M$5*MIN(COUNT(H26:H52), M$5) -> 2.6815024 | M26: 6 | P26: 2036 | Q26: =(Q$40-Q$14)/(P$40-P$14)*(P26-P$14)+Q$14 -> 50.615385 | R26: =(R$40-R$14)/(Q$40-Q$14)*(Q26-Q$14)+R$14 -> 50.615385 | S26: =(S$40-S$14)/(R$40-R$14)*(R26-R$14)+S$14 -> 46.619433 | T26: =(T$40-T$14)/(S$40-S$14)*(S26-S$14)+T$14 -> 43.955466 | U26: =(U$40-U$14)/(T$40-T$14)*(T26-T$14)+U$14 -> 42.623482 | V26: =(V$40-V$14)/(U$40-U$14)*(U26-U$14)+V$14 -> 42.623482 | W26: =(W$40-W$14)/(V$40-V$14)*(V26-V$14)+W$14 -> 42.623482 | X26: =(X$40-X$14)/(W$40-W$14)*(W26-W$14)+X$14 -> 47.951417 | ... AN26: =(AN$40-AN$14)/(AM$40-AM$14)*(AM26-AM$14)+AN$14 -> 59.939271
A27: 2038 | B27: =A$4/C$4/E$4*COUNT(A27:A$39) -> 1.625 | D27: 38 | H27: 2032 | I27: =I$14*(I$45/I$14)^((H27-H$14)/(H$45-H$14)) -> 2.3667076 | K27: =I27/M$5*MIN(COUNT(H27:H53), M$5) -> 2.2483722 | M27: 6 | P27: 2037 | Q27: =(Q$40-Q$14)/(P$40-P$14)*(P27-P$14)+Q$14 -> 51.666667 | R27: =(R$40-R$14)/(Q$40-Q$14)*(Q27-Q$14)+R$14 -> 51.666667 | S27: =(S$40-S$14)/(R$40-R$14)*(R27-R$14)+S$14 -> 47.587719 | T27: =(T$40-T$14)/(S$40-S$14)*(S27-S$14)+T$14 -> 44.868421 | U27: =(U$40-U$14)/(T$40-T$14)*(T27-T$14)+U$14 -> 43.508772 | V27: =(V$40-V$14)/(U$40-U$14)*(U27-U$14)+V$14 -> 43.508772 | W27: =(W$40-W$14)/(V$40-V$14)*(V27-V$14)+W$14 -> 43.508772 | X27: =(X$40-X$14)/(W$40-W$14)*(W27-W$14)+X$14 -> 48.947368 | ... AN27: =(AN$40-AN$14)/(AM$40-AM$14)*(AM27-AM$14)+AN$14 -> 61.184211
A28: 2039 | B28: =A$4/C$4/E$4*COUNT(A28:A$39) -> 1.5 | D28: 38 | H28: 2033 | I28: =I$14*(I$45/I$14)^((H28-H$14)/(H$45-H$14)) -> 2.0888681 | K28: =I28/M$5*MIN(COUNT(H28:H54), M$5) -> 1.8799813 | M28: 6 | P28: 2038 | Q28: =(Q$40-Q$14)/(P$40-P$14)*(P28-P$14)+Q$14 -> 52.717949 | R28: =(R$40-R$14)/(Q$40-Q$14)*(Q28-Q$14)+R$14 -> 52.717949 | S28: =(S$40-S$14)/(R$40-R$14)*(R28-R$14)+S$14 -> 48.556005 | T28: =(T$40-T$14)/(S$40-S$14)*(S28-S$14)+T$14 -> 45.781377 | U28: =(U$40-U$14)/(T$40-T$14)*(T28-T$14)+U$14 -> 44.394062 | V28: =(V$40-V$14)/(U$40-U$14)*(U28-U$14)+V$14 -> 44.394062 | W28: =(W$40-W$14)/(V$40-V$14)*(V28-V$14)+W$14 -> 44.394062 | X28: =(X$40-X$14)/(W$40-W$14)*(W28-W$14)+X$14 -> 49.94332 | ... AN28: =(AN$40-AN$14)/(AM$40-AM$14)*(AM28-AM$14)+AN$14 -> 62.42915
A29: 2040 | B29: =A$4/C$4/E$4*COUNT(A29:A$39) -> 1.375 | D29: 38 | H29: 2034 | I29: =I$14*(I$45/I$14)^((H29-H$14)/(H$45-H$14)) -> 1.8436455 | K29: =I29/M$5*MIN(COUNT(H29:H55), M$5) -> 1.5670987 | M29: 6 | P29: 2039 | Q29: =(Q$40-Q$14)/(P$40-P$14)*(P29-P$14)+Q$14 -> 53.769231 | R29: =(R$40-R$14)/(Q$40-Q$14)*(Q29-Q$14)+R$14 -> 53.769231 | S29: =(S$40-S$14)/(R$40-R$14)*(R29-R$14)+S$14 -> 49.524291 | T29: =(T$40-T$14)/(S$40-S$14)*(S29-S$14)+T$14 -> 46.694332 | U29: =(U$40-U$14)/(T$40-T$14)*(T29-T$14)+U$14 -> 45.279352 | V29: =(V$40-V$14)/(U$40-U$14)*(U29-U$14)+V$14 -> 45.279352 | W29: =(W$40-W$14)/(V$40-V$14)*(V29-V$14)+W$14 -> 45.279352 | X29: =(X$40-X$14)/(W$40-W$14)*(W29-W$14)+X$14 -> 50.939271 | ... AN29: =(AN$40-AN$14)/(AM$40-AM$14)*(AM29-AM$14)+AN$14 -> 63.674089
A30: 2041 | B30: =A$4/C$4/E$4*COUNT(A30:A$39) -> 1.25 | D30: 38 | H30: 2035 | I30: =I$14*(I$45/I$14)^((H30-H$14)/(H$45-H$14)) -> 1.6272109 | K30: =I30/M$5*MIN(COUNT(H30:H56), M$5) -> 1.3017687 | M30: 6 | P30: 2040 | Q30: =(Q$40-Q$14)/(P$40-P$14)*(P30-P$14)+Q$14 -> 54.820513 | R30: =(R$40-R$14)/(Q$40-Q$14)*(Q30-Q$14)+R$14 -> 54.820513 | S30: =(S$40-S$14)/(R$40-R$14)*(R30-R$14)+S$14 -> 50.492578 | T30: =(T$40-T$14)/(S$40-S$14)*(S30-S$14)+T$14 -> 47.607287 | U30: =(U$40-U$14)/(T$40-T$14)*(T30-T$14)+U$14 -> 46.164642 | V30: =(V$40-V$14)/(U$40-U$14)*(U30-U$14)+V$14 -> 46.164642 | W30: =(W$40-W$14)/(V$40-V$14)*(V30-V$14)+W$14 -> 46.164642 | X30: =(X$40-X$14)/(W$40-W$14)*(W30-W$14)+X$14 -> 51.935223 | ... AN30: =(AN$40-AN$14)/(AM$40-AM$14)*(AM30-AM$14)+AN$14 -> 64.919028
... A39: 2050 | B39: =A$4/C$4/E$4*COUNT(A39:A$39) -> 0.125 | D39: 0 | H39: 2044 | I39: =I$14*(I$45/I$14)^((H39-H$14)/(H$45-H$14)) -> 0.528861 | K39: =I39/M$5*MIN(COUNT(H39:H65), M$5) -> 0.29087355 | M39: 0 | P39: 2049 | Q39: =(Q$40-Q$14)/(P$40-P$14)*(P39-P$14)+Q$14 -> 64.282051 | R39: =(R$40-R$14)/(Q$40-Q$14)*(Q39-Q$14)+R$14 -> 64.282051 | S39: =(S$40-S$14)/(R$40-R$14)*(R39-R$14)+S$14 -> 59.207152 | T39: =(T$40-T$14)/(S$40-S$14)*(S39-S$14)+T$14 -> 55.823887 | U39: =(U$40-U$14)/(T$40-T$14)*(T39-T$14)+U$14 -> 54.132254 | V39: =(V$40-V$14)/(U$40-U$14)*(U39-U$14)+V$14 -> 54.132254 | W39: =(W$40-W$14)/(V$40-V$14)*(V39-V$14)+W$14 -> 54.132254 | X39: =(X$40-X$14)/(W$40-W$14)*(W39-W$14)+X$14 -> 60.898785 | ... AN39: =(AN$40-AN$14)/(AM$40-AM$14)*(AM39-AM$14)+AN$14 -> 76.123482
H40: 2045 | I40: =I$14*(I$45/I$14)^((H40-H$14)/(H$45-H$14)) -> 0.46677539 | K40: =I40/M$5*MIN(COUNT(H40:H66), M$5) -> 0.25672646 | M40: 0 | P40: 2050 | Q40: 65.333333 | R40: 65.333333 | S40: 60.175439 | T40: 56.736842 | U40: 55.017544 | V40: 55.017544 | W40: 55.017544 | X40: 61.894737 | Y40: 70.491228 | Z40: 77.368421 | AA40: 79.087719 | AB40: 80.807018 | AC40: 84.245614 | AD40: 85.964912 | AE40: 87.684211 | AF40: 91.122807 | AG40: 92.842105 | AH40: 98 | AI40: 98 | AJ40: 94.561404 | AK40: 91.122807 | AL40: 87.684211 | AM40: 82.526316 | AN40: 77.368421
H41: 2046 | I41: =I$14*(I$45/I$14)^((H41-H$14)/(H$45-H$14)) -> 0.41197832 | K41: =I41/M$5*MIN(COUNT(H41:H67), M$5) -> 0.22658808 | M41: 0
H42: 2047 | I42: =I$14*(I$45/I$14)^((H42-H$14)/(H$45-H$14)) -> 0.36361415 | K42: =I42/M$5*MIN(COUNT(H42:H68), M$5) -> 0.19998778 | M42: 0
H43: 2048 | I43: =I$14*(I$45/I$14)^((H43-H$14)/(H$45-H$14)) -> 0.32092769 | K43: =I43/M$5*MIN(COUNT(H43:H69), M$5) -> 0.17651023 | M43: 0
H44: 2049 | I44: =I$14*(I$45/I$14)^((H44-H$14)/(H$45-H$14)) -> 0.2832524 | K44: =I44/M$5*MIN(COUNT(H44:H70), M$5) -> 0.15578882 | M44: 0
H45: 2050 | I45: 0.25 | K45: =I45/M$5*MIN(COUNT(H45:H71), M$5) -> 0.1375 | M45: 0
A48: Results
A49: nsq | B49: cost
A60: Overleaf data | G60: Results | M60: 2050 results
A61: year | B61: cable_cost | C61: battery_cost | D61: existing_cable | E61: existing_battery | F61: peak_load | G61: battery_investment | H61: cable_investment | I61: battery_installed | J61: cable_installed | K61: lost_load | M61: hour | N61: battery_setpoint | O61: load_net | P61: load_original
A62: 2025 | B62: 3.25 | C62: 5.6725681 | D62: 74 | E62: 6 | F62: =AH15 -> 58.576923 | G62: 0 | H62: 0 | I62: 6 | J62: 74 | K62: 0 | M62: 0 | N62: 14.667 | O62: 80 | P62: 65.333
A63: 2026 | B63: 3.125 | C63: 5.0066373 | D63: 74 | E63: 6 | F63: =AH16 -> 60.153846 | G63: 0 | H63: 0 | I63: 6 | J63: 74 | K63: 0 | M63: 1 | N63: 0 | O63: 65.333 | P63: 65.333
...

Sheet results
A1: Cable only | G1: with battery option
G2: more modular, declining price?
A3: Year | B3: z | C3: Margin | D3: Cumcost | E3: xsea | G3: z | H3: xbat | I3: margin | J3: cumcost | K3: xsea | L3: xbatcum
A4: 2019 | B4: 0 | C4: 43.272 | D4: 0 | E4: =projections!E2+SUM($B$4:B4)*40 -> 74 | G4: 0 | H4: 0 | I4: 43.272 | J4: 0 | K4: 74 | L4: 0
A5: 2020 | B5: 0 | C5: 39.058 | D5: 0 | E5: =projections!E3+SUM($B$4:B5)*40 -> 74 | G5: 0 | H5: 0 | I5: 39.058 | J5: 0 | K5: 74 | L5: 0
A6: 2021 | B6: 0 | C6: 38.866 | D6: 0 | E6: =projections!E4+SUM($B$4:B6)*40 -> 74 | G6: 0 | H6: 0 | I6: 38.866 | J6: 0 | K6: 74 | L6: 0
A7: 2022 | B7: 0 | C7: 35.802 | D7: 0 | E7: =projections!E5+SUM($B$4:B7)*40 -> 74 | G7: 0 | H7: 0 | I7: 35.802 | J7: 0 | K7: 74 | L7: 0
A8: 2023 | B8: 0 | C8: 34.844 | D8: 0 | E8: =projections!E6+SUM($B$4:B8)*40 -> 74 | G8: 0 | H8: 0 | I8: 34.844 | J8: 0 | K8: 74 | L8: 0
A9: 2024 | B9: 0 | C9: 33.311 | D9: 0 | E9: =projections!E7+SUM($B$4:B9)*40 -> 74 | G9: 0 | H9: 0 | I9: 33.311 | J9: 0 | K9: 74 | L9: 0
A10: 2025 | B10: 0 | C10: 32.545 | D10: 0 | E10: =projections!E8+SUM($B$4:B10)*40 -> 74 | G10: 0 | H10: 0 | I10: 32.545 | J10: 0 | K10: 74 | L10: 0
A11: 2026 | B11: 0 | C11: 31.013 | D11: 0 | E11: =projections!E9+SUM($B$4:B11)*40 -> 74 | G11: 0 | H11: 0 | I11: 31.013 | J11: 0 | K11: 74 | L11: 0
A12: 2027 | B12: 0 | C12: 29.672 | D12: 0 | E12: =projections!E10+SUM($B$4:B12)*40 -> 74 | G12: 0 | H12: 0 | I12: 29.672 | J12: 0 | K12: 74 | L12: 0
A13: 2028 | B13: 0 | C13: 28.331 | D13: 0 | E13: =projections!E11+SUM($B$4:B13)*40 -> 74 | G13: 0 | H13: 0 | I13: 28.331 | J13: 0 | K13: 74 | L13: 0
A14: 2029 | B14: 0 | C14: 26.798 | D14: 0 | E14: =projections!E12+SUM($B$4:B14)*40 -> 74 | G14: 0 | H14: 0 | I14: 26.798 | J14: 0 | K14: 74 | L14: 0
A15: 2030 | B15: 0 | C15: 24.883 | D15: 0 | E15: =projections!E13+SUM($B$4:B15)*40 -> 74 | G15: 0 | H15: 0 | I15: 24.883 | J15: 0 | K15: 74 | L15: 0
... A28: 2043 | B28: 0 | C28: 1.045 | D28: 70 | E28: =projections!E26+SUM($B$4:B28)*40 -> 78 | G28: 0 | H28: 0 | I28: 1.045 | J28: 70 | K28: 78 | L28: 0
A29: 2044 | B29: 1 | C29: 39.896 | D29: 105 | E29: =projections!E27+SUM($B$4:B29)*40 -> 118 | G29: 0 | H29: 1 | I29: 0.896 | J29: 71.38 | K29: 78 | L29: 1 | N29: Build a smaller battery than currently installed?
A30: 2045 | B30: 0 | C30: 39.13 | D30: 105 | E30: =projections!E28+SUM($B$4:B30)*40 -> 118 | G30: 0 | H30: 0 | I30: 0.13 | J30: 71.38 | K30: 78 | L30: 1
A31: 2046 | B31: 0 | C31: 37.98 | D31: 105 | E31: =projections!E29+SUM($B$4:B31)*40 -> 118 | G31: 0 | H31: 1.02 | I31: 0 | J31: 72.2164 | K31: 78 | L31: 2.02
A32: 2047 | B32: 1 | C32: 39.214 | D32: 125 | E32: =projections!E30+SUM($B$4:B32)*40 -> 120 | G32: 1 | H32: 0 | I32: 1.234 | J32: 92.2164 | K32: 80 | L32: 2.02
A33: 2048 | B33: 0 | C33: 38.256 | D33: 125 | E33: =projections!E31+SUM($B$4:B33)*40 -> 120 | G33: 0 | H33: 0 | I33: 0.276 | J33: 92.2164 | K33: 80 | L33: 2.02
A34: 2049 | B34: 0 | C34: 37.682 | D34: 125 | E34: =projections!E32+SUM($B$4:B34)*40 -> 120 | G34: 0 | H34: 1.064 | I34: 0.766 | J34: 92.4611 | K34: 80 | L34: 3.084
A35: 2050 | B35: 0 | C35: 36.916 | D35: 125 | E35: =projections!E33+SUM($B$4:B35)*40 -> 120 | G35: 0 | H35: 0 | I35: 0 | J35: 92.4611 | K35: 80 | L35: 3.084

Sheet ev_charging
A1: Plugshare | B1: no charger | G1: https://driver.chargepoint.com/mapCenter/41.28284176295081/-70.06561941963004/13?view=list
A2: https://www.nantucket-ma.gov/2770/EV-Charging-Stations
G3: Chargepoint | J3: Power (kW) | K3: Total power (MW)
A4: Public charging stations | G4: 28 | H4: stations all AC | J4: 7 | K4: =G4*J4/1000 -> 0.196
A5: 0.3 | B5: $/kWh | C5: for the first 3 hours
A8: Town policy
A9: https://www.nantucket-ma.gov/DocumentCenter/View/46466/Electric-Vehicle-Charging-Station-Cost-Recovery-Policy-PDF

Sheet annual_peaks_estimated_data
A1: Year | B1: Normal_50_50 | C1: Extreme_90_10 | D1: Extreme_95_5 | E1: Actuals | F1: Summer_50_50 | H1: All peaks in MW after DER impact
A2: 2006 | B2: 36.21163 | C2: 37.552527 | D2: 38.893423 | E2: 39.170507 | F2: 36.21163 | H2: Normal 50/50 weather is the average weather on the past 20 annual peak days.
A3: 2007 | B3: 40.23432 | C3: 42.149887 | D3: 43.68234 | E3: 38.801843 | F3: 40.23432 | H3: • Extreme 90/10 weather is such that it is expected that 90% of the time it should not be exceeded.
A4: 2008 | B4: 39.65965 | C4: 41.000547 | D4: 42.533 | E4: 38.617512 | F4: 39.65965 | H4: It is similarly inferred that it should occur no more than one time in a ten-year period on average.
A5: 2009 | B5: 40.042763 | C5: 41.766773 | D5: 43.299227 | E5: 39.170507 | F5: 40.042763 | H5: • Extreme 95/5 weather is such that it is expected that 95% of the time it should not be exceeded.
A6: 2010 | B6: 38.51031 | C6: 41.000547 | D6: 42.533 | E6: 39.907834 | F6: 38.51031 | H6: It is similarly inferred that it should occur no more than one time in a twenty-year period on average.
A7: 2011 | B7: 41.192103 | C7: 43.10767 | D7: 44.83168 | E7: 40.645161 | F7: 41.192103
A8: 2012 | B8: 44.640123 | C8: 45.98102 | D8: 47.321917 | E8: 44.147465 | F8: 44.640123 | H8: https://www.mass.gov/doc/gmacesmp-draftnational-grid/download
A9: 2013 | B9: 44.065453 | C9: 46.364133 | D9: 47.896587 | E9: 45.437788 | F9: 44.065453 | H9: p. 557
A10: 2014 | B10: 44.448567 | C10: 46.747247 | D10: 48.2797 | E10: 40.460829 | F10: 44.448567
A11: 2015 | B11: 43.490783 | C11: 46.364133 | D11: 47.896587 | E11: 45.253456 | F11: 43.490783
A12: 2016 | B12: 48.471257 | C12: 51.919277 | D12: 53.643287 | E12: 49.861751 | F12: 48.471257
A13: 2017 | B13: 45.214793 | C13: 47.513473 | D13: 49.237483 | E13: 45.62212 | F13: 45.214793
A14: 2018 | B14: 48.088143 | C14: 52.30239 | D14: 54.0264 | E14: 49.677419 | F14: 48.088143
A15: 2019 | B15: 46.747247 | C15: 49.42904 | D15: 51.72772 | E15: 50.599078 | F15: 46.747247
A16: 2020 | B16: 48.088143 | C16: 53.834843 | D16: 55.941967 | E16: 52.073733 | F16: 48.088143
A17: 2021 | B17: 51.15305 | C17: 54.60107 | D17: 56.133523 | E17: 52.81106 | F17: 51.15305
A18: 2022 | B18: 51.536163 | C18: 56.708193 | D18: 59.19843 | E18: 58.2 | F18: 51.536163
A19: 2023 | B19: 52.493947 | C19: 58.240647 | D19: 60.156213 | F19: 52.493947
A20: 2024 | B20: 53.45173 | C20: 59.581543 | D20: 61.688667 | F20: 53.45173
A21: 2025 | B21: 54.409513 | C21: 60.34777 | D21: 62.454893 | F21: 54.409513
A22: 2026 | B22: 55.558853 | C22: 61.880223 | D22: 63.987347 | F22: 55.558853
A23: 2027 | B23: 56.89975 | C23: 63.22112 | D23: 65.328243 | F23: 56.89975
A24: 2028 | B24: 58.04909 | C24: 64.562017 | D24: 66.66914 | F24: 58.04909
A25: 2029 | B25: 59.389987 | C25: 66.09447 | D25: 68.201593 | F25: 59.389987
A26: 2030 | B26: 60.730883 | C26: 67.626923 | D26: 70.11716 | F26: 60.730883
A27: 2031 | B27: 62.263337 | C27: 69.350933 | D27: 71.649613 | F27: 62.263337
A28: 2032 | B28: 63.604233 | C28: 71.074943 | D28: 73.182067 | F28: 63.604233
A29: 2033 | B29: 65.5198 | C29: 72.798953 | D29: 75.097633 | F29: 65.5198
A30: 2034 | B30: 67.052253 | C30: 74.71452 | D30: 77.0132 | F30: 67.052253
... A46: 2050 | B46: 85.824807 | C46: 95.40264 | D46: 98.084433 | F46: 85.824807

Sheet overview
C1: Inventory of Retired Generators as of August 2024
C3: Entity ID | D3: Entity Name | E3: Plant ID | F3: Plant Name | G3: Google Map | H3: Bing Map | I3: Plant State | J3: County | K3: Balancing Authority Code | L3: Sector | M3: Generator ID | N3: Unit Code | O3: Nameplate Capacity (MW) | P3: Net Summer Capacity (MW) | Q3: Net Winter Capacity (MW) | R3: Technology | S3: Energy Source Code | T3: Prime Mover Code | U3: Operating Month | V3: Operating Year | W3: Retirement Month | X3: Retirement Year | Y3: Nameplate Energy Capacity (MWh) | Z3: DC Net Capacity (MW) | AA3: Latitude | AB3: Longitude
C4: 13206 | D4: Nantucket Electric Co | E4: 1615 | F4: Nantucket Hybrid | G4: Map | H4: Map | I4: MA | J4: Nantucket | K4: ISNE | L4: Electric Utility | M4: 12 | O4: 3.7 | P4: 2.8 | Q4: 3 | R4: Petroleum Liquids | S4: DFO | T4: GT | U4: 10 | V4: 1988 | W4: 8 | X4: 2019 | AA4: 41.2583 | AB4: -70.0517
C5: 13206 | D5: Nantucket Electric Co | E5: 1615 | F5: Nantucket Hybrid | G5: Map | H5: Map | I5: MA | J5: Nantucket | K5: ISNE | L5: Electric Utility | M5: 13 | O5: 3.7 | P5: 2.9 | Q5: 3.3 | R5: Petroleum Liquids | S5: DFO | T5: GT | U5: 10 | V5: 1988 | W5: 8 | X5: 2019 | AA5: 41.2583 | AB5: -70.0517
C6: 13206 | D6: Nantucket Electric Co | E6: 1615 | F6: Nantucket Hybrid | G6: Map | H6: Map | I6: MA | J6: Nantucket | K6: ISNE | L6: Electric Utility | M6: 14 | O6: 2.5 | P6: 2.5 | Q6: 2.5 | R6: Petroleum Liquids | S6: DFO | T6: IC | U6: 4 | V6: 1995 | W6: 8 | X6: 2007 | AA6: 41.2583 | AB6: -70.0517
C7: 13206 | D7: Nantucket Electric Co | E7: 1615 | F7: Nantucket Hybrid | G7: Map | H7: Map | I7: MA | J7: Nantucket | K7: ISNE | L7: Electric Utility | M7: 15 | O7: 2.5 | P7: 2.5 | Q7: 2.5 | R7: Petroleum Liquids | S7: DFO | T7: IC | U7: 4 | V7: 1995 | W7: 8 | X7: 2007 | AA7: 41.2583 | AB7: -70.0517
C8: 13206 | D8: Nantucket Electric Co | E8: 1615 | F8: Nantucket Hybrid | G8: Map | H8: Map | I8: MA | J8: Nantucket | K8: ISNE | L8: Electric Utility | M8: 16 | O8: 2.5 | P8: 2.5 | Q8: 2.5 | R8: Petroleum Liquids | S8: DFO | T8: IC | U8: 2 | V8: 1998 | W8: 8 | X8: 2007 | AA8: 41.2583 | AB8: -70.0517
C9: 13206 | D9: Nantucket Electric Co | E9: 1615 | F9: Nantucket Hybrid | G9: Map | H9: Map | I9: MA | J9: Nantucket | K9: ISNE | L9: Electric Utility | M9: 17 | O9: 2.5 | P9: 2.5 | Q9: 2.5 | R9: Petroleum Liquids | S9: DFO | T9: IC | U9: 2 | V9: 1998 | W9: 8 | X9: 2007 | AA9: 41.2583 | AB9: -70.0517
C10: 13206 | D10: Nantucket Electric Co | E10: 1615 | F10: Nantucket Hybrid | G10: Map | H10: Map | I10: MA | J10: Nantucket | K10: ISNE | L10: Electric Utility | M10: 10 | O10: 1.2 | P10: 1 | Q10: 1 | R10: Petroleum Liquids | S10: DFO | T10: IC | U10: 7 | V10: 1987 | W10: 6 | X10: 2006 | AA10: 41.2583 | AB10: -70.0517
C11: 13206 | D11: Nantucket Electric Co | E11: 1615 | F11: Nantucket Hybrid | G11: Map | H11: Map | I11: MA | J11: Nantucket | K11: ISNE | L11: Electric Utility | M11: 11 | O11: 1.2 | P11: 1 | Q11: 1 | R11: Petroleum Liquids | S11: DFO | T11: IC | U11: 7 | V11: 1987 | W11: 6 | X11: 2006 | AA11: 41.2583 | AB11: -70.0517
A13: Inventory of Operating Generators as of August 2024
A15: Entity ID | B15: Entity Name | C15: Plant ID | D15: Plant Name | E15: Google Map | F15: Bing Map | G15: Plant State | H15: County | I15: Balancing Authority Code | J15: Sector | K15: Generator ID | L15: Unit Code | M15: Nameplate Capacity (MW) | N15: Net Summer Capacity (MW) | O15: Net Winter Capacity (MW) | P15: Technology | Q15: Energy Source Code | R15: Prime Mover Code | S15: Operating Month | T15: Operating Year | U15: Planned Retirement Month | V15: Planned Retirement Year | W15: Status | X15: Nameplate Energy Capacity (MWh) | Y15: DC Net Capacity (MW) | Z15: Planned Derate Year | AA15: Planned Derate Month | AB15: Planned Derate of Summer Capacity (MW) | AC15: Planned Uprate Year | AD15: Planned Uprate Month | AE15: Planned Uprate of Summer Capacity (MW) | AF15: Latitude | AG15: Longitude
A16: 13206 | B16: Nantucket Electric Co | C16: 1615 | D16: Nantucket Hybrid | E16: Map | F16: Map | G16: MA | H16: Nantucket | I16: ISNE | J16: Electric Utility | K16: 18 | M16: 15.4 | N16: 13.5 | O16: 15.4 | P16: Petroleum Liquids | Q16: DFO | R16: GT | S16: 8 | T16: 2019 | W16: (OP) Operating | AF16: 41.2583 | AG16: -70.0517
A17: 13206 | B17: Nantucket Electric Co | C17: 1615 | D17: Nantucket Hybrid | E17: Map | F17: Map | G17: MA | H17: Nantucket | I17: ISNE | J17: Electric Utility | K17: 19 | M17: 1 | N17: 1 | O17: 1 | P17: Petroleum Liquids | Q17: DFO | R17: IC | S17: 8 | T17: 2019 | W17: (OP) Operating | AF17: 41.2583 | AG17: -70.0517
A18: 13206 | B18: Nantucket Electric Co | C18: 1615 | D18: Nantucket Hybrid | E18: Map | F18: Map | G18: MA | H18: Nantucket | I18: ISNE | J18: Electric Utility | K18: 20 | M18: 6 | N18: 6 | O18: 6 | P18: Batteries | Q18: MWH | R18: BA | S18: 7 | T18: 2019 | W18: (OP) Operating | X18: 48 | AF18: 41.2583 | AG18: -70.0517

Sheet traffic
A1: https://nantucket-ma.civilspace.io/en/projects/transportation
A2: traffic counters are part of strategic plan
A4: https://www.nantucket-ma.gov/3254/Traffic-Data
A6: https://geodot-homepage-massdot.hub.arcgis.com/pages/massvehiclecensus

Sheet solar
A1: https://www.nantucket-ma.gov/1156/Solar-Map-Resources
A3: also has a map with solar installations
